#VRML_SIM R2025a utf8

EXTERNPROTO "https://raw.githubusercontent.com/cyberbotics/webots/R2025a/projects/objects/backgrounds/protos/TexturedBackground.proto"
EXTERNPROTO "https://raw.githubusercontent.com/cyberbotics/webots/R2025a/projects/objects/backgrounds/protos/TexturedBackgroundLight.proto"
EXTERNPROTO "https://raw.githubusercontent.com/cyberbotics/webots/R2025a/projects/objects/floors/protos/RectangleArena.proto"
EXTERNPROTO "https://raw.githubusercontent.com/cyberbotics/webots/R2025a/projects/objects/balls/protos/Ball.proto"

WorldInfo {
  basicTimeStep 20
}
Viewpoint {
  orientation -0.57589725008214 0.5751778423581764 0.5809585243440549 2.0900816217902145
  position -0.00010876222666357646 0.06900789395667155 2.1110259254063792
}
TexturedBackground {
}
TexturedBackgroundLight {
}
Robot {
  translation 0 0 2
  children [
    HingeJoint {
      device [
        RotationalMotor {
          name "yaw_motor"
        }
      ]
      endPoint Solid {
        children [
          HingeJoint {
            device [
              RotationalMotor {
                name "pitch_motor"
              }
            ]
            endPoint DEF CAM Camera {
              name "camera"
              recognition Recognition {
              }
            }
          }
        ]
      }
    }
  ]
  controller "tracker"
  supervisor TRUE
}
DEF BALL Ball {
  translation 0 0 0.032446044999999986
}
RectangleArena {
}
